<?xml version="1.0" encoding="utf-8"?>
<robot name="patasmonkey_v6">
	<!-- ① Nav2 / TF のルートとなるフレーム -->
	<!-- inertial / visual / collision を書かなければ、実質「質量ゼロ・大きさゼロ」の仮想リンクとして扱われます -->
	<link name="base_link"/>
	<link name="body_left_link">
		<inertial>
			<mass value="5.977149333128697"/>
			<origin rpy="0 0 0" xyz="2.7075088848408945e-14 -0.07491905752363066 0.05992194832635813"/>
			<inertia ixx="0.018521735026712373" ixy="-5.106774023738348e-15" ixz="1.4632239957780798e-15" iyy="0.05171445416669546" iyz="-3.735988253558275e-05" izz="0.05594377143878953"/>
		</inertial>
		<collision name="body_left_link_collision">
			<origin rpy="0.0 -0.0 0.0" xyz="0.0 0.0 0.0"/>
			<geometry>
				<mesh filename="package://patasmonkey_description/meshes/body_left.stl" scale="0.001 0.001 0.001"/>
			</geometry>
		</collision>
		<visual name="body_left_link_visual">
			<origin rpy="0.0 -0.0 0.0" xyz="0.0 0.0 0.0"/>
			<geometry>
				<mesh filename="package://patasmonkey_description/meshes/body_left.stl" scale="0.001 0.001 0.001"/>
			</geometry>
		</visual>
	</link>
	<link name="body_right_link">
		<inertial>
			<mass value="5.933952434141838"/>
			<origin rpy="0 0 0" xyz="1.0817157499107769e-14 0.06546443954277502 -7.861985990547521e-05"/>
			<inertia ixx="0.018269321974895048" ixy="1.1848658946447257e-14" ixz="-1.474498890486474e-15" iyy="0.05170095487155976" iyz="3.710544736609336e-05" izz="0.05569135865378952"/>
		</inertial>
		<collision name="body_right_link_collision">
			<origin rpy="0.0 -0.0 0.0" xyz="0.0 -0.01 -0.06"/>
			<geometry>
				<mesh filename="package://patasmonkey_description/meshes/body_right.stl" scale="0.001 0.001 0.001"/>
			</geometry>
		</collision>
		<visual name="body_right_link_visual">
			<origin rpy="0.0 -0.0 0.0" xyz="0.0 -0.01 -0.06"/>
			<geometry>
				<mesh filename="package://patasmonkey_description/meshes/body_right.stl" scale="0.001 0.001 0.001"/>
			</geometry>
		</visual>
	</link>
	<link name="wheel_arm_frontleft_link">
		<inertial>
			<mass value="0.06867212404052492"/>
			<origin rpy="0 0 0" xyz="-0.07517540966320621 -0.0050000000000000044 -0.027361611466174954"/>
			<inertia ixx="2.7839444321380923e-05" ixy="0.0" ixz="-4.773177745386561e-05" iyy="0.00016830338776518633" iyz="5.551115123125783e-21" izz="0.0001416084788444838"/>
		</inertial>
		<collision name="wheel_arm_frontleft_link_collision">
			<origin rpy="0.0 -0.3490658503988659 0.0" xyz="0.0 -0.009999999999999981 0.0"/>
			<geometry>
				<mesh filename="package://patasmonkey_description/meshes/wheel_arm.stl" scale="0.001 0.001 0.001"/>
			</geometry>
		</collision>
		<visual name="wheel_arm_frontleft_link_visual">
			<origin rpy="0.0 -0.3490658503988659 0.0" xyz="0.0 -0.009999999999999981 0.0"/>
			<geometry>
				<mesh filename="package://patasmonkey_description/meshes/wheel_arm.stl" scale="0.001 0.001 0.001"/>
			</geometry>
		</visual>
	</link>
	<link name="wheel_arm_rearleft_link">
		<inertial>
			<mass value="0.06867212404052492"/>
			<origin rpy="0 0 0" xyz="0.07517540966253877 -0.004999999999999977 -0.02736161146593201"/>
			<inertia ixx="2.783944432138057e-05" ixy="-1.7763568394002505e-19" ixz="4.773177745386535e-05" iyy="0.00016830338776518668" iyz="0.0" izz="0.0001416084788444831"/>
		</inertial>
		<collision name="wheel_arm_rearleft_link_collision">
			<origin rpy="0.0 0.3490658503988659 0.0" xyz="0.1503508193257451 -0.009999999999999981 -0.05472322293210698"/>
			<geometry>
				<mesh filename="package://patasmonkey_description/meshes/wheel_arm.stl" scale="0.001 0.001 0.001"/>
			</geometry>
		</collision>
		<visual name="wheel_arm_rearleft_link_visual">
			<origin rpy="0.0 0.3490658503988659 0.0" xyz="0.1503508193257451 -0.009999999999999981 -0.05472322293210698"/>
			<geometry>
				<mesh filename="package://patasmonkey_description/meshes/wheel_arm.stl" scale="0.001 0.001 0.001"/>
			</geometry>
		</visual>
	</link>
	<link name="wheel_arm_rearright_link">
		<inertial>
			<mass value="0.06867212404052492"/>
			<origin rpy="0 0 0" xyz="0.07517540966253881 0.004999999999999977 -0.027361611465932023"/>
			<inertia ixx="2.783944432138057e-05" ixy="0.0" ixz="4.773177745386559e-05" iyy="0.00016830338776518633" iyz="0.0" izz="0.00014160847884448345"/>
		</inertial>
		<collision name="wheel_arm_rearright_link_collision">
			<origin rpy="0.0 0.3490658503988659 0.0" xyz="0.15035081932574507 0.0 -0.05472322293210699"/>
			<geometry>
				<mesh filename="package://patasmonkey_description/meshes/wheel_arm.stl" scale="0.001 0.001 0.001"/>
			</geometry>
		</collision>
		<visual name="wheel_arm_rearright_link_visual">
			<origin rpy="0.0 0.3490658503988659 0.0" xyz="0.15035081932574507 0.0 -0.05472322293210699"/>
			<geometry>
				<mesh filename="package://patasmonkey_description/meshes/wheel_arm.stl" scale="0.001 0.001 0.001"/>
			</geometry>
		</visual>
	</link>
	<link name="wheel_arm_frontright_link">
		<inertial>
			<mass value="0.06867212404052492"/>
			<origin rpy="0 0 0" xyz="-0.07517540966320628 0.0050000000000000044 -0.027361611466174968"/>
			<inertia ixx="2.7839444321380214e-05" ixy="-1.7763568394002505e-19" ixz="-4.773177745386547e-05" iyy="0.0001683033877651864" iyz="5.551115123125783e-21" izz="0.0001416084788444831"/>
		</inertial>
		<collision name="wheel_arm_frontright_link_collision">
			<origin rpy="0.0 -0.3490658503988659 0.0" xyz="0.0 0.0 -6.938893903907228e-18"/>
			<geometry>
				<mesh filename="package://patasmonkey_description/meshes/wheel_arm.stl" scale="0.001 0.001 0.001"/>
			</geometry>
		</collision>
		<visual name="wheel_arm_frontright_link_visual">
			<origin rpy="0.0 -0.3490658503988659 0.0" xyz="0.0 0.0 -6.938893903907228e-18"/>
			<geometry>
				<mesh filename="package://patasmonkey_description/meshes/wheel_arm.stl" scale="0.001 0.001 0.001"/>
			</geometry>
		</visual>
	</link>
	<link name="frontleft_wheel_link">
		<inertial>
			<mass value="0.6459736269326636"/>
			<origin rpy="0 0 0" xyz="-8.862355294070312e-14 -0.025000000000000022 -3.235953172087136e-14"/>
			<inertia ixx="0.0020372715927300987" ixy="-2.842170943040401e-18" ixz="1.815529060422705e-13" iyy="0.0038053875071388916" iyz="-7.105427357601002e-19" izz="0.002037271592297401"/>
		</inertial>
		<collision name="frontleft_wheel_link_collision">
			<origin rpy="0.0 -0.34906585039886656 0.0" xyz="0.0 -0.04999999999999999 -3.469446951953614e-18"/>
			<geometry>
				<mesh filename="package://patasmonkey_description/meshes/wheel.stl" scale="0.001 0.001 0.001"/>
			</geometry>
		</collision>
		<visual name="frontleft_wheel_link_visual">
			<origin rpy="0.0 -0.34906585039886656 0.0" xyz="0.0 -0.04999999999999999 -3.469446951953614e-18"/>
			<geometry>
				<mesh filename="package://patasmonkey_description/meshes/wheel.stl" scale="0.001 0.001 0.001"/>
			</geometry>
		</visual>
	</link>
	<link name="rearleft_wheel_link">
		<inertial>
			<mass value="0.6459736269326636"/>
			<origin rpy="0 0 0" xyz="-8.867906409193438e-14 -0.025000000000000022 3.2182589926321725e-14"/>
			<inertia ixx="0.002037271592730113" ixy="-2.842170943040401e-18" ixz="-1.8153585301661223e-13" iyy="0.0038053875071388916" iyz="-3.552713678800501e-19" izz="0.0020372715922973897"/>
		</inertial>
		<collision name="rearleft_wheel_link_collision">
			<origin rpy="0.0 0.3490658503988664 0.0" xyz="0.0 -0.04999999999999999 0.0"/>
			<geometry>
				<mesh filename="package://patasmonkey_description/meshes/wheel.stl" scale="0.001 0.001 0.001"/>
			</geometry>
		</collision>
		<visual name="rearleft_wheel_link_visual">
			<origin rpy="0.0 0.3490658503988664 0.0" xyz="0.0 -0.04999999999999999 0.0"/>
			<geometry>
				<mesh filename="package://patasmonkey_description/meshes/wheel.stl" scale="0.001 0.001 0.001"/>
			</geometry>
		</visual>
	</link>
	<link name="rearright_wheel_link">
		<inertial>
			<mass value="0.6459736269326636"/>
			<origin rpy="0 0 0" xyz="-8.867906409193438e-14 0.024999999999999967 3.2182589926321725e-14"/>
			<inertia ixx="0.002037271592730113" ixy="-2.842170943040401e-18" ixz="-1.8153585301661223e-13" iyy="0.0038053875071388916" iyz="0.0" izz="0.0020372715922973897"/>
		</inertial>
		<collision name="rearright_wheel_link_collision">
			<origin rpy="0.0 0.3490658503988659 0.0" xyz="0.0 0.0 0.0"/>
			<geometry>
				<mesh filename="package://patasmonkey_description/meshes/wheel.stl" scale="0.001 0.001 0.001"/>
			</geometry>
		</collision>
		<visual name="rearright_wheel_link_visual">
			<origin rpy="0.0 0.3490658503988659 0.0" xyz="0.0 0.0 0.0"/>
			<geometry>
				<mesh filename="package://patasmonkey_description/meshes/wheel.stl" scale="0.001 0.001 0.001"/>
			</geometry>
		</visual>
	</link>
	<link name="frontright_wheel_link">
		<inertial>
			<mass value="0.6459736269326636"/>
			<origin rpy="0 0 0" xyz="-8.865130851631875e-14 0.024999999999999994 -3.2356062273919406e-14"/>
			<inertia ixx="0.0020372715927301018" ixy="-2.842170943040401e-18" ixz="1.815525507709026e-13" iyy="0.0038053875071388916" iyz="-7.105427357601002e-19" izz="0.002037271592297401"/>
		</inertial>
		<collision name="frontright_wheel_link_collision">
			<origin rpy="0.0 -0.3490658503988659 0.0" xyz="0.0 0.0 0.0"/>
			<geometry>
				<mesh filename="package://patasmonkey_description/meshes/wheel.stl" scale="0.001 0.001 0.001"/>
			</geometry>
		</collision>
		<visual name="frontright_wheel_link_visual">
			<origin rpy="0.0 -0.3490658503988659 0.0" xyz="0.0 0.0 0.0"/>
			<geometry>
				<mesh filename="package://patasmonkey_description/meshes/wheel.stl" scale="0.001 0.001 0.001"/>
			</geometry>
		</visual>
	</link>

	<!-- ② base_link から body_left_link への固定ジョイント -->
  	<joint name="base_to_body_left" type="fixed">
    	<parent link="base_link"/>
    	<child  link="body_left_link"/>
    	<!-- とりあえず body_left_link の座標系を base_link と一致させる -->
    	<origin xyz="0 0 0" rpy="0 0 0"/>
  	</joint>
	<joint name="rev0" type="continuous">
		<parent link="body_left_link"/>
		<child link="body_right_link"/>
		<origin rpy="0 0 0" xyz="0.0 0.01 0.06"/>
		<axis xyz="0.0 1.0 0.0"/>
	</joint>
	<joint name="rev1" type="continuous">
		<parent link="body_left_link"/>
		<child link="wheel_arm_frontleft_link"/>
		<origin rpy="0 0 0" xyz="-0.029999999999999964 -0.15 0.029999999999999895"/>
		<axis xyz="0.0 1.0 0.0"/>
	</joint>
	<joint name="rev2" type="continuous">
		<parent link="body_left_link"/>
		<child link="wheel_arm_rearleft_link"/>
		<origin rpy="0 0 0" xyz="0.030000000000000054 -0.15 0.029999999999999992"/>
		<axis xyz="0.0 1.0 0.0"/>
	</joint>
	<joint name="rev3" type="continuous">
		<parent link="body_right_link"/>
		<child link="wheel_arm_rearright_link"/>
		<origin rpy="0 0 0" xyz="0.02999999999999993 0.13999999999999996 -0.029999999999999954"/>
		<axis xyz="0.0 -1.0 0.0"/>
	</joint>
	<joint name="rev4" type="continuous">
		<parent link="body_right_link"/>
		<child link="wheel_arm_frontright_link"/>
		<origin rpy="0 0 0" xyz="-0.03 0.13999999999999996 -0.029999999999999992"/>
		<axis xyz="0.0 -1.0 0.0"/>
	</joint>
	<joint name="rev5" type="continuous">
		<parent link="wheel_arm_frontleft_link"/>
		<child link="frontleft_wheel_link"/>
		<origin rpy="0 0 0" xyz="-0.15035081932574496 -0.00999999999999987 -0.054723222932106956"/>
		<axis xyz="0.0 -0.9999999999999978 0.0"/>
	</joint>
	<joint name="rev6" type="continuous">
		<parent link="wheel_arm_rearleft_link"/>
		<child link="rearleft_wheel_link"/>
		<origin rpy="0 0 0" xyz="0.15035081932574518 -0.00999999999999987 -0.05472322293210702"/>
		<axis xyz="0.0 -0.9999999999999987 0.0"/>
	</joint>
	<joint name="rev7" type="continuous">
		<parent link="wheel_arm_rearright_link"/>
		<child link="rearright_wheel_link"/>
		<origin rpy="0 0 0" xyz="0.1503508193257454 0.009999999999999953 -0.05472322293210703"/>
		<axis xyz="0.0 -0.9999999999999981 0.0"/>
	</joint>
	<joint name="rev8" type="continuous">
		<parent link="wheel_arm_frontright_link"/>
		<child link="frontright_wheel_link"/>
		<origin rpy="0 0 0" xyz="-0.15035081932574537 0.009999999999999981 -0.054723222932107005"/>
		<axis xyz="0.0 -0.9999999999999982 0.0"/>
	</joint>
</robot>